Workbook

Sheet Calculator
A1: Kwikly Growth Diagnostic Calculator
A2: What the office enters and sees. Blue cells are inputs. Green cells are pulled from the Math & Norms tab.
A4: WHAT THE OFFICE ENTERS
A5: Hygiene chairs | B5: 2
A6: Hygiene patients per chair, per day | B6: 8
A7: Shifts unworked per month | B7: 2 | C7: Shifts a chair sits empty
A8: Weeks out booking new patients | B8: 16 | C8: How far out the schedule is booked
A10: WHAT THE OFFICE SEES
A11: Active patients (estimated) | B11: ='Math & Norms'!B29 -> 2016 | C11: Derived from chairs and patients per day
A12: Booked revenue you protect (per year) | B12: ='Math & Norms'!B36 -> 28800 | C12: Reliable coverage locks most of it back in (this could be lower if we change the fill rate)
A13: Currently lost to staffing gaps (per year) | B13: ='Math & Norms'!B35 -> 28800 | C13: Before Kwikly coverage
A14: Stuck in your backlog (per year) | B14: ='Math & Norms'!B61 -> 66876.923 | C14: New patients lost plus revenue left on the table
A15: New patients who go elsewhere | B15: ='Math & Norms'!B51 -> 37800 | C15: True loss
A16: Recurring revenue left on the table | B16: ='Math & Norms'!B45 -> 29076.923 | C16: Seen fewer times than recall calls for
A17: Your opportunity with Kwikly (per year) | B17: ='Math & Norms'!B63 -> 95676.923 | C17: Protect plus backlog
A18: Recommended per diem shifts per month | B18: ='Math & Norms'!B71 -> 6 | C18: Cover gaps plus dig out
A20: REP TALKING POINT (not shown on the page)
A21: Downstream treatment at stake (per year) | B21: ='Math & Norms'!B56 -> 171360 | C21: 40% x $1,700.
A22: Total opportunity including downstream | B22: ='Math & Norms'!B65 -> 267036.92 | C22: Core opportunity plus the downstream talking point

Sheet Math & Norms
A1: Behind the Scenes: Math, Assumptions, and Norms
A2: Blue = assumptions you can change. Black = calculated. Green = pulled from the Calculator tab. Yellow = key levers worth a close look.
A4: BENCHMARKS AND NORMS
A5: Working days per month | B5: 21 | C5: Industry norm, about 21
A6: Production per cleaning visit | B6: 150 | C6: Includes the doctor exam; PPO norm
A7: Production per perio visit | B7: 250 | C7: Devin; not in the research pass
A8: Target cleaning visits per year | B8: 2 | C8: Every 6 months; validated
A9: Target perio visits per year | B9: 4 | C9: Every 3 months; clinical standard
A10: Perio share of patient panel | B10: 0.25 | C10: From Devin's note in Slack
A11: New patients per chair per month | B11: 15 | C11: Devin said 30 a month per practice; 30 per chair = 30 at 2 chairs
A12: Shifts filled with Kwikly | B12: 1 | C12: We could use our standard fill rate here if we didnt' want to promise all shifts would be filled
A13: New patient value horizon (years) | B13: 1 | C13: We bank one year of recall
A14: Untreated cleanings with downstream potential | B14: 0.4 | C14: Devin gave us this. Gross potential, before case acceptance
A15: Downstream revenue per case | B15: 1700 | C15: Devin gave us this data. Should note that our researched benchmark is ~$500 to $900; $1,700 implies a crown or implant heavy mix
A17: NEW PATIENT LOSS BY BOOKING DISTANCE
A18: Weeks out | B18: Share lost | C18: From the original calculator; not in the research pass
A19: 4 or less | B19: 0
A20: 5 to 8 | B20: 0.1
A21: 9 to 13 | B21: 0.2
A22: 14 to 26 | B22: 0.35
A23: 27 or more | B23: 0.5
A25: DERIVED
A26: Cleaning (prophy) share of panel | B26: =1-B10 -> 0.75 | C26: 100% minus perio, so no double count
A27: Cleaning recall interval (months) | B27: =12/B8 -> 6 | C27: 12 / cleaning visits per year
A28: Perio recall interval (months) | B28: =12/B9 -> 3 | C28: 12 / perio visits per year
A29: Active patient panel | B29: =Calculator!B5*Calculator!B6*B5*12/2 -> 2016 | C29: chairs x patients/day x days x 12 / 2
A30: Production per chair per day | B30: =Calculator!B6*B6 -> 1200 | C30: patients/day x cleaning visit value
A31: Backlog in months | B31: =Calculator!B8*12/52 -> 3.6923077 | C31: weeks out x 12 / 52
A32: Value per new patient (horizon) | B32: =B8*B6*B13 -> 300 | C32: cleaning visits/yr x value x horizon
A34: THE MATH: STAFFING GAPS (PROTECT)
A35: Production at risk per year | B35: =Calculator!B7*12*B30 -> 28800 | C35: shifts unworked x 12 x prod per chair per day
A36: Recovered with Kwikly (you protect) | B36: =B35*B12 -> 28800 | C36: at risk x fill rate
A38: THE MATH: BACKLOG, EXISTING PATIENTS
A39: Perio loss factor | B39: =IF(B31>B28,MIN((B31-B28)/B28,B9),0) -> 0.23076923 | C39: (months - interval) / interval, capped. Counts past 3 months
A40: Lost perio visits per year | B40: =B39*B29*B10 -> 116.30769 | C40: factor x panel x perio share
A41: Perio revenue lost | B41: =B40*B7 -> 29076.923 | C41: x perio visit value
A42: Cleaning loss factor | B42: =IF(B31>B27,MIN((B31-B27)/B27,B8),0) -> 0 | C42: same shape; counts only past 6 months
A43: Lost cleaning visits per year | B43: =B42*B29*B26 -> 0 | C43: factor x panel x cleaning share
A44: Cleaning revenue lost | B44: =B43*B6 -> 0 | C44: x cleaning visit value
A45: Recurring revenue left on the table | B45: =B41+B44 -> 29076.923 | C45: perio lost plus cleaning lost
...
